Workbook

Sheet Разлики
A1: Склад за дост. | B1: Доставчик | C1: Vendor No | D1: Начин на подаване | E1: Номер прием | F1: Вътрешен номер | G1: Активен номер | H1: Delivery No | I1: Invoice No | J1: Invoice Date | K1: Ref. Number SUPPLIER | L1: Other Supplier Ref Num | M1: Price | N1: QTY | O1: Received QTY | P1: Difference | Q1: Подал разликата | R1: Стойност във валутата на доставчика | S1: Стойност (в лева) | T1: Дата на подаване | U1: СТАТУС - Попълва се от централата! | V1: № документа за разлики | W1: Дата на документа за разлики | X1: При фактура - дата на приема в Навижън | Y1: Обработени в B01 | Z1: Номер на клетка за минуси | AA1: Намерени БРОЙКИ (след подаването им) | AB1: Подадена информация към дост. за намерени бройки след подаването им (ДАТА) | AC1: Допълнителен коментар | AD1: ДАТА на намиране в В01 на липсващи артикули или коментар от склада | AE1: дата на прием в Навижън | AF1: working days after goods receipt in navision | AG1: БРАНД | AH1: РМ | AI1: формула Ники | AJ1: INV | AK1: INV | AL1: INV positiv | AM1: Разлика между + и инв. | AN1: дата на прием от таблицата на Тони | AO1: номер на склада - програмата | AP1: системен номер на доставка на склада
A2: B01 | B2: AISIN EUROPE SA | C2: VEN0000901 | D2: =IFERROR(HYPERLINK(INDEX(вендори!F:F,MATCH(C2,вендори!A:A,0)),INDEX(вендори!F:F,MATCH(C2,вендори!A:A,0))),"") -> 0 | E2: 25136237 | F2: BF3841 | G2: AISWPT-181 | H2: 313086 | I2: 25136237 | J2: 45952 | K2: WPT-181 | M2: 34,02 | N2: 0 | O2: 8 | P2: 8 | Q2: Плюс | R2: 272.16 | S2: 532.29869 | T2: 45972 | U2: Отказани | AE2: 45965 | AF2: 6 | AI2: 25136237|BF3841 | AN2: 45758 | AO2: 16128 | AP2: 7195
A3: B01 | B3: Auger Autotechnik GmbH | C3: VEN0001821 | D3: =IFERROR(HYPERLINK(INDEX(вендори!F:F,MATCH(C3,вендори!A:A,0)),INDEX(вендори!F:F,MATCH(C3,вендори!A:A,0))),"") -> 0 | E3: 95091282 | F3: C65242 | G3: AUG70793 | H3: 80220627 | I3: 95091282 | J3: 45946 | K3: 70793 | L3: 70793 | M3: 7.77 | N3: 12 | O3: 6 | P3: -6 | Q3: Минус | R3: -46.62 | S3: -91.180795 | T3: 45972 | U3: Получено КИ | V3: 10028768 | W3: 45975 | AE3: 45960 | AF3: 9 | AG3: AUGER | AH3: MKEHAYOVA | AI3: 95091282|C65242 | AN3: 45788 | AO3: 16178 | AP3: 7093
A4: B01 | B4: CARPASSION SP. ZO.O | C4: VEN0002939 | D4: =IFERROR(HYPERLINK(INDEX(вендори!F:F,MATCH(C4,вендори!A:A,0)),INDEX(вендори!F:F,MATCH(C4,вендори!A:A,0))),"") -> 0 | E4: FS113102025CARP | F4: H1393F | G4: CP 10061CP | H4: FS/113/10/2025/CARP | I4: FS/113/10/2025/CARP | J4: 45950 | K4: CP 10061CP | L4: 0 | M4: 8.84 | N4: 4 | O4: 0 | P4: -4 | Q4: Минус | R4: -35.36 | S4: -69.158149 | T4: 45972 | U4: МАСЛА - обработва се от РМ | AE4: 45966 | AF4: 5 | AG4: CARPASSION | AH4: ALAZAROV | AI4: FS113102025CARP|H1393F | AN4: 45911 | AO4: 16392 | AP4: 7296
A5: B01 | B5: CARPASSION SP. ZO.O | C5: VEN0002939 | D5: =IFERROR(HYPERLINK(INDEX(вендори!F:F,MATCH(C5,вендори!A:A,0)),INDEX(вендори!F:F,MATCH(C5,вендори!A:A,0))),"") -> 0 | E5: FS113102025CARP | F5: C4BD8B | G5: MMT CP10061 | H5: FS/113/10/2025/CARP | I5: FS/113/10/2025/CARP | J5: 45950 | K5: 10061 | L5: 10061__10061 | M5: 8.84 | N5: 50 | O5: 54 | P5: 4 | Q5: Плюс | R5: 35.36 | S5: 69.158149 | T5: 45972 | U5: МАСЛА - обработва се от РМ | AE5: 45966 | AF5: 5 | AG5: CARPASSION | AH5: ALAZAROV | AI5: FS113102025CARP|C4BD8B | AN5: 45911 | AO5: 16393 | AP5: 7296
A6: B01 | B6: CMI Filtration Belgium | C6: VEN0002552 | D6: =IFERROR(HYPERLINK(INDEX(вендори!F:F,MATCH(C6,вендори!A:A,0)),INDEX(вендори!F:F,MATCH(C6,вендори!A:A,0))),"") -> 0 | E6: 1040023819 | F6: F4A6B4 | G6: FF253 | H6: 19374240 | I6: 1040023819 | J6: 45950 | K6: FF0025300MF | L6: FF0025300MF | M6: 8.9 | N6: 12 | O6: 2 | P6: -10 | Q6: Минус | R6: -89 | S6: -174.06887 | T6: 45972 | U6: Получено КИ | V6: 5000005053 | W6: 45996 | AE6: 45958 | AF6: 11 | AG6: FLEETGUARD | AH6: VAPETROV | AI6: 1040023819|F4A6B4 | AN6: 30/10/2025 | AO6: 15908 | AP6: 7041
A7: B01 | B7: ContiTech Antriebssysteme GmbH | C7: VEN0000263 | D7: =IFERROR(HYPERLINK(INDEX(вендори!F:F,MATCH(C7,вендори!A:A,0)),INDEX(вендори!F:F,MATCH(C7,вендори!A:A,0))),"") -> деливъри | E7: 9956682 | F7: F8C210 | G7: CT 1218 | H7: 33056367 | I7: 9956682 | J7: 45930 | K7: CT1218 | L7: CT1218 | M7: 7.06 | N7: 246 | O7: 146 | P7: -100 | Q7: Минус | R7: -706 | S7: -1380.816 | T7: 45972 | U7: Получено КИ | V7: 3000130827 | W7: 46051 | X7: по сметка | AC7: вече са инв. | AE7: 45938 | AF7: 25 | AG7: CONTITECH | AH7: VAPETROV | AI7: 9956682|F8C210 | AN7: 45910 | AO7: 14348 | AP7: 6402
A8: B01 | B8: ContiTech Antriebssysteme GmbH | C8: VEN0000263 | D8: =IFERROR(HYPERLINK(INDEX(вендори!F:F,MATCH(C8,вендори!A:A,0)),INDEX(вендори!F:F,MATCH(C8,вендори!A:A,0))),"") -> деливъри | E8: 9956682 | F8: G109Z0 | G8: 6 PK 1033 K1 | H8: 33056367 | I8: 9956682 | J8: 45930 | K8: 6PK1033K1 | L8: 6PK1033K1 | M8: 24.16 | N8: 23 | O8: 21 | P8: -2 | Q8: Минус | R8: -48.32 | S8: -94.505706 | T8: 45972 | U8: Получено КИ | V8: 3000130827 | W8: 46051 | X8: по сметка | AC8: вече са инв. | AE8: 45938 | AF8: 25 | AG8: CONTITECH | AH8: VAPETROV | AI8: 9956682|G109Z0 | AN8: 45910 | AO8: 14347 | AP8: 6402
A9: B01 | B9: ContiTech Antriebssysteme GmbH | C9: VEN0000263 | D9: =IFERROR(HYPERLINK(INDEX(вендори!F:F,MATCH(C9,вендори!A:A,0)),INDEX(вендори!F:F,MATCH(C9,вендори!A:A,0))),"") -> деливъри | E9: 9961090 | F9: E79DA3 | G9: CT 1099 WP1 | H9: 33079802 | I9: 9961090 | J9: 45951 | K9: CT1099WP1 | L9: CT1099WP1 | M9: 92.04 | N9: 9 | O9: 8 | P9: -1 | Q9: Минус | R9: -92.04 | S9: -180.01459 | T9: 45972 | U9: Подадена | AE9: 45960 | AF9: 9 | AG9: CONTITECH | AH9: VAPETROV | AI9: 9961090|E79DA3 | AN9: 31/10/2025 | AO9: 15964 | AP9: 7134
A10: B01 | B10: ContiTech Antriebssysteme GmbH | C10: VEN0000263 | D10: =IFERROR(HYPERLINK(INDEX(вендори!F:F,MATCH(C10,вендори!A:A,0)),INDEX(вендори!F:F,MATCH(C10,вендори!A:A,0))),"") -> деливъри | E10: 9961090 | F10: A6754D | G10: CT 1092 K1 | H10: 33079802 | I10: 9961090 | J10: 45951 | K10: CT1092K1 | M10: 37.67 | N10: 0 | O10: 1 | P10: 1 | Q10: Плюс | R10: 37.67 | S10: 73.676116 | T10: 45972 | U10: Получено ДИ/фактура | V10: 3000130828 | W10: 46051 | AE10: 45961 | AF10: 8 | AI10: 9961090|A6754D | AN10: 31/10/2025 | AO10: 15967 | AP10: 7134
A11: B01 | B11: ContiTech Antriebssysteme GmbH | C11: VEN0000263 | D11: =IFERROR(HYPERLINK(INDEX(вендори!F:F,MATCH(C11,вендори!A:A,0)),INDEX(вендори!F:F,MATCH(C11,вендори!A:A,0))),"") -> деливъри | E11: 9961090 | F11: A79B9D | G11: 7 PK 2035 | H11: 33079802 | I11: 9961090 | J11: 45951 | K11: 7PK2035 | L11: 7PK2035 | M11: 13.18 | N11: 160 | O11: 170 | P11: 10 | Q11: Плюс | R11: 131.8 | S11: 257.77839 | T11: 45972 | U11: Получено ДИ/фактура | V11: 3000130828 | W11: 46051 | AE11: 45960 | AF11: 9 | AG11: CONTITECH | AH11: VAPETROV | AI11: 9961090|A79B9D | AN11: 31/10/2025 | AO11: 15969 | AP11: 7134
A12: B01 | B12: DENSO Europe B.V. | C12: VEN0001937 | D12: =IFERROR(HYPERLINK(INDEX(вендори!F:F,MATCH(C12,вендори!A:A,0)),INDEX(вендори!F:F,MATCH(C12,вендори!A:A,0))),"") -> 0 | E12: TA25024769 | F12: D2EC6C | G12: DCRI300460 | H12: 1157003 | 1158201 | I12: TA 25024769 | J12: 45947 | K12: DCRI300460 | L12: DCRI300460 | M12: 177.16 | N12: 4 | O12: 3 | P12: -1 | Q12: Минус | R12: -177.16 | S12: -346.49484 | T12: 45972 | U12: Отказани | AE12: 45951 | AF12: 16 | AG12: DENSO | AH12: KMINKOV | AI12: TA25024769|D2EC6C | AN12: 30/10/2025 | AO12: 15891 | AP12: 6809
A13: B01 | B13: DENSO Europe B.V. | C13: VEN0001937 | D13: =IFERROR(HYPERLINK(INDEX(вендори!F:F,MATCH(C13,вендори!A:A,0)),INDEX(вендори!F:F,MATCH(C13,вендори!A:A,0))),"") -> 0 | E13: TA25024769 | F13: 9EDCDA | G13: KJ16CR-L11 | H13: 1157003 | 1158201 | I13: TA 25024769 | J13: 45947 | K13: KJ16CR-L11 | L13: KJ16CR-L11 | M13: 1.39 | N13: 350 | O13: 370 | P13: 20 | Q13: Плюс | R13: 27.8 | S13: 54.372074 | T13: 45972 | U13: Отказани | AE13: 45951 | AF13: 16 | AG13: DENSO | AH13: KMINKOV | AI13: TA25024769|9EDCDA | AN13: 30/10/2025 | AO13: 15892 | AP13: 6809
A14: B01 | B14: DENSO Europe B.V. | C14: VEN0001937 | D14: =IFERROR(HYPERLINK(INDEX(вендори!F:F,MATCH(C14,вендори!A:A,0)),INDEX(вендори!F:F,MATCH(C14,вендори!A:A,0))),"") -> 0 | E14: TA25025315 | F14: B2A864 | G14: DCP17023 | H14: TA | 25025315 | I14: TA 25025315 | J14: 45952 | K14: DCP17023 | L14: DCP17023 | M14: 193 | N14: 2 | O14: 0 | P14: -2 | Q14: Минус | R14: -386 | S14: -754.95038 | T14: 45972 | U14: Отказани | AE14: 45959 | AF14: 10 | AG14: DENSO | AH14: KMINKOV | AI14: TA25025315|B2A864 | AN14: 45668 | AO14: 16041 | AP14: 7074
A15: B01 | B15: DENSO Europe B.V. | C15: VEN0001937 | D15: =IFERROR(HYPERLINK(INDEX(вендори!F:F,MATCH(C15,вендори!A:A,0)),INDEX(вендори!F:F,MATCH(C15,вендори!A:A,0))),"") -> 0 | E15: TA25025315 | F15: CFE3A3 | G15: DRR09034 | H15: TA | 25025315 | I15: TA 25025315 | J15: 45952 | K15: DRR09034 | L15: DRR09034 | M15: 31.3 | N15: 22 | O15: 21 | P15: -1 | Q15: Минус | R15: -31.3 | S15: -61.217479 | T15: 45972 | U15: Отказани | AE15: 45959 | AF15: 10 | AG15: DENSO | AH15: KMINKOV | AI15: TA25025315|CFE3A3 | AN15: 45668 | AO15: 16042 | AP15: 7074
A16: B01 | B16: DIESEL TECHNIC SE | C16: VEN0001277 | D16: =IFERROR(HYPERLINK(INDEX(вендори!F:F,MATCH(C16,вендори!A:A,0)),INDEX(вендори!F:F,MATCH(C16,вендори!A:A,0))),"") -> https://partnerportal.dieseltechnic.com/en/infocenter/forms | E16: BCI0758795 | F16: D4A2AA | G16: 7.49010 | H16: BCI0758795 | I16: BCI0758795 | J16: 45950 | K16: 7.49010 | L16: 7.49010 | M16: 161.11 | N16: 1 | O16: 0 | P16: -1 | Q16: Минус | R16: -161.11 | S16: -315.10377 | T16: 45972 | U16: Получено КИ | V16: BCC0179970 + ДИ BCI0770360/27.11.25 | W16: 45978 | X16: по сметка | AA16: 1 | AB16: 45987 | AC16: поскано ДИ - ок | AD16: 45986 | AE16: 45957 | AF16: 12 | AG16: DT | AH16: AGEORGIEV | AI16: BCI0758795|D4A2AA | AN16: 45819 | AO16: 16205 | AP16: 6994
A17: B01 | B17: DIESEL TECHNIC SE | C17: VEN0001277 | D17: =IFERROR(HYPERLINK(INDEX(вендори!F:F,MATCH(C17,вендори!A:A,0)),INDEX(вендори!F:F,MATCH(C17,вендори!A:A,0))),"") -> https://partnerportal.dieseltechnic.com/en/infocenter/forms | E17: BCI0760404 | F17: F5271B | G17: 4.90772 | H17: BCS2114647 | I17: BCI0760404 | J17: 45954 | K17: 4.90772 | L17: 4.90772 | M17: 0.76 | N17: 1000 | O17: 1101 | P17: 101 | Q17: Плюс | R17: 76.76 | S17: 150.12951 | T17: 45972 | U17: Получено ДИ/фактура | V17: BCI0766921 | W17: 45978 | X17: CM 19.11.25 | AE17: 45960 | AF17: 9 | AG17: DT | AH17: KDOBREV | AI17: BCI0760404|F5271B | AN17: 45727 | AO17: 16058 | AP17: 7142
A18: B01 | B18: EXEDY CLUTCH EUROPE LIMITED | C18: VEN0002388 | D18: =IFERROR(HYPERLINK(INDEX(вендори!F:F,MATCH(C18,вендори!A:A,0)),INDEX(вендори!F:F,MATCH(C18,вендори!A:A,0))),"") -> 0 | E18: PSI065267 | F18: BBA0C4 | G18: NSS2198 | H18: PSI065267 | I18: PSI065267 | J18: 45958 | K18: NSS2198 | L18: NSS2198 | M18: 77.96 | N18: 3 | O18: 0 | P18: -3 | Q18: Минус | R18: -233.88 | S18: -457.42952 | T18: 45972 | U18: Анулирана | AE18: 45966 | AF18: 5 | AG18: EXEDY | AH18: AGEORGIEV | AI18: PSI065267|BBA0C4 | AN18: 45819 | AO18: 16221 | AP18: 7319
A19: B01 | B19: EXEDY CLUTCH EUROPE LIMITED | C19: VEN0002388 | D19: =IFERROR(HYPERLINK(INDEX(вендори!F:F,MATCH(C19,вендори!A:A,0)),INDEX(вендори!F:F,MATCH(C19,вендори!A:A,0))),"") -> 0 | E19: PSI065267 | F19: XXXX | G19: NS656152 | H19: PSI065267 | I19: PSI065267 | J19: 45958 | K19: NS656152 | M19: 77.96 | N19: 0 | O19: 3 | P19: 3 | Q19: Плюс | R19: 233.88 | S19: 457.42952 | T19: 45972 | U19: Анулирана | AC19: АГ - не излиза, да искаме връщане/Exedy Japan’s part number for ECE NSS2198 = NS656152 | AE19: 45966 | AF19: 5 | AI19: PSI065267|XXXX | AN19: 45819 | AO19: 16222 | AP19: 7319
A20: B01 | B20: FEDERAL-MOGUL GLOBAL AFTERMARKET EMEA BV | C20: VEN0001842 | D20: =IFERROR(HYPERLINK(INDEX(вендори!F:F,MATCH(C20,вендори!A:A,0)),INDEX(вендори!F:F,MATCH(C20,вендори!A:A,0))),"") -> https://afjt3vcvh.accounts.ondemand.com/saml2/idp/sso/afjt3vcvh.accounts.ondemand.com | E20: 3000682023 | F20: G0KLUF | G20: FOL252 | H20: 34587751 | 34587752 | 34587753 | 34587754 | 34587755 | 34587756 | I20: 3000682023 | J20: 45952 | K20: FOL252 | L20: FOL252__FOL252 | M20: 9.14 | N20: 16 | O20: 0 | P20: -16 | Q20: Минус | R20: -146.24 | S20: -286.02058 | T20: 45972 | U20: Отказани | AA20: 16 | AB20: ок | AC20: Ticket Number: 336733 | AD20: 45994 | AE20: 45957 | AF20: 12 | AG20: AE | AH20: AGEORGIEV | AI20: 3000682023|G0KLUF | AN20: 45668 | AO20: 16011 | AP20: 6988
A21: B01 | B21: FERDINAND BILSTEIN GMBH + CO. KG | C21: VEN0001136 | D21: =IFERROR(HYPERLINK(INDEX(вендори!F:F,MATCH(C21,вендори!A:A,0)),INDEX(вендори!F:F,MATCH(C21,вендори!A:A,0))),"") -> 0 | E21: 12417309 | F21: D16439 | G21: FE40372 | H21: 708644501 | 708644756 | I21: 12417309 | J21: 45943 | K21: 40372 | L21: 40372 | M21: 28.35 | N21: 2 | O21: 0 | P21: -2 | Q21: Минус | R21: -56.7 | S21: -110.89556 | T21: 45972 | U21: Получено КИ | V21: 93276984 | W21: 45975 | AE21: 45950 | AF21: 17 | AG21: FEBI | AH21: KDOBREV | AI21: 12417309|D16439 | AN21: 29/10/2025 | AO21: 15827 | AP21: 6790
A22: B01 | B22: FERDINAND BILSTEIN GMBH + CO. KG | C22: VEN0001136 | D22: =IFERROR(HYPERLINK(INDEX(вендори!F:F,MATCH(C22,вендори!A:A,0)),INDEX(вендори!F:F,MATCH(C22,вендори!A:A,0))),"") -> 0 | E22: 12422146 | F22: C354B1 | G22: FE34367 | H22: 708685998 | 708686069 | I22: 12422146 | J22: 45951 | K22: 34367 | L22: 34367 | M22: 4.32 | N22: 56 | O22: 0 | P22: -56 | Q22: Минус | R22: -241.92 | S22: -473.15439 | T22: 45972 | U22: Отказани | AE22: 45959 | AF22: 10 | AG22: FEBI | AH22: KDOBREV | AI22: 12422146|C354B1 | AN22: 45880 | AO22: 16336 | AP22: 7060
A23: B01 | B23: FERDINAND BILSTEIN GMBH + CO. KG | C23: VEN0001136 | D23: =IFERROR(HYPERLINK(INDEX(вендори!F:F,MATCH(C23,вендори!A:A,0)),INDEX(вендори!F:F,MATCH(C23,вендори!A:A,0))),"") -> 0 | E23: 12422146 | F23: G13CNO | G23: FE179812 | H23: 708685998 | 708686069 | I23: 12422146 | J23: 45951 | K23: 179812 | L23: 179812 | M23: 130.59 | N23: 1 | O23: 0 | P23: -1 | Q23: Минус | R23: -130.59 | S23: -255.41184 | T23: 45972 | U23: Отказани | AE23: 45959 | AF23: 10 | AG23: FEBI | AH23: MKEHAYOVA | AI23: 12422146|G13CNO | AN23: 45880 | AO23: 16333 | AP23: 7060
A24: B01 | B24: FERDINAND BILSTEIN GMBH + CO. KG | C24: VEN0001136 | D24: =IFERROR(HYPERLINK(INDEX(вендори!F:F,MATCH(C24,вендори!A:A,0)),INDEX(вендори!F:F,MATCH(C24,вендори!A:A,0))),"") -> 0 | E24: 12422146 | F24: B9F387 | G24: FE32232 | H24: 708685998 | 708686069 | I24: 12422146 | J24: 45951 | K24: 32232 | L24: 32232 | M24: 63.2 | N24: 2 | O24: 1 | P24: -1 | Q24: Минус | R24: -63.2 | S24: -123.60846 | T24: 45972 | U24: Отказани | AE24: 45959 | AF24: 10 | AG24: FEBI | AH24: KDOBREV | AI24: 12422146|B9F387 | AN24: 45880 | AO24: 16335 | AP24: 7060
A25: B01 | B25: FERDINAND BILSTEIN GMBH + CO. KG | C25: VEN0001136 | D25: =IFERROR(HYPERLINK(INDEX(вендори!F:F,MATCH(C25,вендори!A:A,0)),INDEX(вендори!F:F,MATCH(C25,вендори!A:A,0))),"") -> 0 | E25: 12422146 | F25: CFB629 | G25: FE38839 | H25: 708685998 | 708686069 | I25: 12422146 | J25: 45951 | K25: 38839 | M25: 35.99 | N25: 0 | O25: 1 | P25: 1 | Q25: Плюс | R25: 35.99 | S25: 70.390322 | T25: 45972 | U25: Отказани | AE25: 45959 | AF25: 10 | AI25: 12422146|CFB629 | AN25: 45880 | AO25: 16339 | AP25: 7060
A26: B01 | B26: FRECCIA INTERNATIONAL S.R.L. | C26: VEN0001243 | D26: =IFERROR(HYPERLINK(INDEX(вендори!F:F,MATCH(C26,вендори!A:A,0)),INDEX(вендори!F:F,MATCH(C26,вендори!A:A,0))),"") -> бланка | E26: 408825 | F26: G0POK1 | G26: RA06-998 | H26: 4088/25 | I26: 4088/25 | J26: 45946 | K26: RA06-998 | L26: RA06-998 | M26: 3.66 | N26: 128 | O26: 176 | P26: 48 | Q26: Плюс | R26: 175.68 | S26: 343.60021 | T26: 45972 | U26: Получено ДИ/фактура | V26: 5140/25 | W26: 46010 | X26: CM 16.01.26 | AE26: 45966 | AF26: 5 | AG26: FRECCIA | AH26: AGEORGIEV | AI26: 408825|G0POK1 | AN26: 45849 | AO26: 16328 | AP26: 7292
A27: B01 | B27: FROGUM SP. Z O.O. | C27: VEN0002039 | D27: =IFERROR(HYPERLINK(INDEX(вендори!F:F,MATCH(C27,вендори!A:A,0)),INDEX(вендори!F:F,MATCH(C27,вендори!A:A,0))),"") -> 0 | E27: 65/10/SU/2025 | F27: C6364F | G27: MMT A040 0077 | H27: номер на доставка 6787 | I27: 65/10/SU/2025 | J27: 45946 | K27: MMT A040 0077 | L27: 0 | M27: 13.03 | N27: 11 | O27: 4 | P27: -7 | Q27: Минус | R27: -91.21 | S27: -178.39125 | T27: 45972 | U27: Получено КИ | V27: 6/11/SU/2025 | W27: 45979 | AE27: 45950 | AF27: 17 | AG27: FROGUM | AH27: ALAZAROV | AI27: 65/10/SU/2025|C6364F | AN27: 31/10/2025 | AO27: 15954 | AP27: -
A28: B01 | B28: FROGUM SP. Z O.O. | C28: VEN0002039 | D28: =IFERROR(HYPERLINK(INDEX(вендори!F:F,MATCH(C28,вендори!A:A,0)),INDEX(вендори!F:F,MATCH(C28,вендори!A:A,0))),"") -> 0 | E28: 65/10/SU/2025 | F28: C63662 | G28: MMT A040 00781 | H28: номер на доставка 6787 | I28: 65/10/SU/2025 | J28: 45946 | K28: MMT A040 00781 | L28: 0 | M28: 13.03 | N28: 5 | O28: 0 | P28: -5 | Q28: Минус | R28: -65.15 | S28: -127.42232 | T28: 45972 | U28: Получено КИ | V28: 6/11/SU/2025 | W28: 45979 | AE28: 45950 | AF28: 17 | AG28: FROGUM | AH28: ALAZAROV | AI28: 65/10/SU/2025|C63662 | AN28: 31/10/2025 | AO28: 15955 | AP28: -
A29: B01 | B29: FROGUM SP. Z O.O. | C29: VEN0002039 | D29: =IFERROR(HYPERLINK(INDEX(вендори!F:F,MATCH(C29,вендори!A:A,0)),INDEX(вендори!F:F,MATCH(C29,вендори!A:A,0))),"") -> 0 | E29: 65/10/SU/2025 | F29: C63646 | G29: MMT A040 0070 | H29: номер на доставка 6787 | I29: 65/10/SU/2025 | J29: 45946 | K29: MMT A040 0070 | M29: 13,03 | N29: 0 | O29: 6 | P29: 6 | Q29: Плюс | R29: 78.18 | S29: 152.90679 | T29: 45972 | U29: Получено ДИ/фактура | V29: 78/11/SU/2025 | W29: 45979 | X29: 45981 | AE29: 45950 | AF29: 17 | AI29: 65/10/SU/2025|C63646 | AN29: 31/10/2025 | AO29: 15956 | AP29: -
A30: B01 | B30: FUCHS LUBRICANTS ROMANIA SRL | C30: VEN0002862 | D30: =IFERROR(HYPERLINK(INDEX(вендори!F:F,MATCH(C30,вендори!A:A,0)),INDEX(вендори!F:F,MATCH(C30,вендори!A:A,0))),"") -> 0 | E30: FAFLRO2411279 | F30: G10U25 | G30: TITAN FFL-8 1L | H30: ALFRO24/11309 | I30: FAFLRO24/11279 | J30: 45959 | K30: 0 | L30: 0 | M30: 8.5 | N30: 12 | O30: 0 | P30: -12 | Q30: Минус | R30: -102 | S30: -199.49466 | T30: 45972 | U30: МАСЛА - обработва се от РМ | AE30: 45960 | AF30: 9 | AG30: FUCHS | AH30: MDRINEV | AI30: FAFLRO2411279|G10U25 | AN30: 45668 | AO30: 16033 | AP30: 7149
A31: B01 | B31: FUCHS LUBRICANTS ROMANIA SRL | C31: VEN0002862 | D31: =IFERROR(HYPERLINK(INDEX(вендори!F:F,MATCH(C31,вендори!A:A,0)),INDEX(вендори!F:F,MATCH(C31,вендори!A:A,0))),"") -> 0 | E31: FAFLRO2411279 | F31: G0FP87 | G31: TITAN FFL-8 20L | H31: ALFRO24/11309 | I31: FAFLRO24/11279 | J31: 45959 | K31: 602060846 | L31: 0602060846__602060846 | M31: 150.2 | N31: 6 | O31: 4 | P31: -2 | Q31: Минус | R31: -300.4 | S31: -587.53133 | T31: 45972 | U31: МАСЛА - обработва се от РМ | AE31: 45960 | AF31: 9 | AG31: FUCHS | AH31: MDRINEV | AI31: FAFLRO2411279|G0FP87 | AN31: 45668 | AO31: 16034 | AP31: 7149
A32: B01 | B32: GKN Ayra Servicio, S.A | C32: VEN0002007 | D32: =IFERROR(HYPERLINK(INDEX(вендори!F:F,MATCH(C32,вендори!A:A,0)),INDEX(вендори!F:F,MATCH(C32,вендори!A:A,0))),"") -> 0 | E32: 1950287339 | F32: E64EB2 | G32: 0.025552 | H32: 1940479267 | 1940479226 | I32: 1950287339 | J32: 45940 | K32: 25552 | L32: 25552 | M32: 5.73 | N32: 3 | O32: 2 | P32: -1 | Q32: Минус | R32: -5.73 | S32: -11.206906 | T32: 45972 | U32: Получено КИ | V32: 1960063351 | W32: 45974 | AE32: 45951 | AF32: 16 | AG32: SPIDAN | AH32: MKEHAYOVA | AI32: 1950287339|E64EB2 | AN32: 23/10/2025 | AO32: 15371 | AP32: 6824
A33: B01 | B33: GROOTHANDEL TRUCK ONDERDELEN B.V. | C33: VEN0002784 | D33: =IFERROR(HYPERLINK(INDEX(вендори!F:F,MATCH(C33,вендори!A:A,0)),INDEX(вендори!F:F,MATCH(C33,вендори!A:A,0))),"") -> 0 | E33: 25813705 | F33: F80404 | G33: DAF1905555 | H33: 25813705 | I33: 25813705 | J33: 45930 | K33: DAF1905555 | L33: 0 | M33: 39.9 | N33: 2 | O33: 0 | P33: -2 | Q33: Минус | R33: -79.8 | S33: -156.07523 | T33: 45972 | U33: изпратени от дост.впосл. | AC33: You will receive it with the next shipment | AE33: 45960 | AF33: 9 | AG33: DAF | AH33: KMINKOV | AI33: 25813705|F80404 | AN33: 45788 | AO33: 16183 | AP33: 7109
A34: B01 | B34: HELLA POLSKA SP. Z O.O. | C34: VEN0001281 | D34: =IFERROR(HYPERLINK(INDEX(вендори!F:F,MATCH(C34,вендори!A:A,0)),INDEX(вендори!F:F,MATCH(C34,вендори!A:A,0))),"") -> 0 | E34: 4625013258 | F34: 451336 | G34: 1AB007 145-001 | H34: 72676359 | I34: 4625013258 | J34: 45957 | K34: 1AB 007 145-001 | L34: 1AB 007 145-001 | M34: 35.26 | N34: 1 | O34: 0 | P34: -1 | Q34: Минус | R34: -35.26 | S34: -68.962566 | T34: 45972 | U34: Получено КИ | V34: 4725004004 | W34: 45987 | AE34: 45966 | AF34: 5 | AG34: HELLA | AH34: DEIVANOV | AI34: 4625013258|451336 | AN34: 45849 | AO34: 16308 | AP34: 7324
A35: B01 | B35: HENGST SE | C35: VEN0001450 | D35: =IFERROR(HYPERLINK(INDEX(вендори!F:F,MATCH(C35,вендори!A:A,0)),INDEX(вендори!F:F,MATCH(C35,вендори!A:A,0))),"") -> 0 | E35: 90688383 | F35: D92BA0 | G35: E491L | H35: 81919855 | 81919856 | I35: 90688383 | J35: 45953 | K35: E491L | L35: E491L | M35: 29.16 | N35: 12 | O35: 11 | P35: -1 | Q35: Минус | R35: -29.16 | S35: -57.032003 | T35: 45972 | U35: Отказани | AE35: 45961 | AF35: 8 | AG35: HENGST | AH35: VAPETROV | AI35: 90688383|D92BA0 | AN35: 45758 | AO35: 16109 | AP35: 7161
A36: B01 | B36: HENGST SE | C36: VEN0001450 | D36: =IFERROR(HYPERLINK(INDEX(вендори!F:F,MATCH(C36,вендори!A:A,0)),INDEX(вендори!F:F,MATCH(C36,вендори!A:A,0))),"") -> 0 | E36: 90688383 | F36: D93015 | G36: E172H D35 | H36: 81919855 | 81919856 | I36: 90688383 | J36: 45953 | K36: E172H D35 | L36: E172H D35 | M36: 4.14 | N36: 80 | O36: 90 | P36: 10 | Q36: Плюс | R36: 41.4 | S36: 80.971362 | T36: 45972 | U36: Получено ДИ/фактура | V36: 90693897 | W36: 45986 | X36: 45988 | AE36: 45961 | AF36: 8 | AG36: HENGST | AH36: VAPETROV | AI36: 90688383|D93015 | AN36: 45758 | AO36: 16110 | AP36: 7161
A37: B01 | B37: INTER CARS MALTA LIMITED | C37: VEN0001490 | D37: =IFERROR(HYPERLINK(INDEX(вендори!F:F,MATCH(C37,вендори!A:A,0)),INDEX(вендори!F:F,MATCH(C37,вендори!A:A,0))),"") -> 0 | E37: SI25/B01/09/00010 | F37: B4EC94 | G37: C3V022ABE | H37: TCLU2299624 | I37: SI25/B01/09/00010 | J37: 45925 | K37: C3V022ABE | L37: 0 | M37: 11.66 | N37: 64 | O37: 0 | P37: -64 | Q37: Минус | R37: -746.24 | S37: -1305.92 | T37: 45972 | U37: Подадена | AE37: 45938 | AF37: 25 | AG37: ABE | AH37: KDOBREV | AI37: SI25/B01/09/00010|B4EC94 | AN37: 25/10/2025 | AO37: 15564 | AP37: 6373
A38: B01 | B38: INTER CARS MALTA LIMITED | C38: VEN0001490 | D38: =IFERROR(HYPERLINK(INDEX(вендори!F:F,MATCH(C38,вендори!A:A,0)),INDEX(вендори!F:F,MATCH(C38,вендори!A:A,0))),"") -> 0 | E38: SI25/B01/10/00006 | F38: B4CCF5 | G38: C10323ABE | H38: ONEU5768174 | I38: SI25/B01/10/00003 | J38: 45936 | K38: C10323ABE | M38: 4,46 | N38: 110 | O38: 100 | P38: -10 | Q38: Минус | R38: -44.6 | S38: -78.05 | T38: 45972 | U38: Отказани | AE38: 45938 | AF38: 25 | AI38: SI25/B01/10/00006|B4CCF5 | AN38: 45849 | AO38: 16304 | AP38: 6695
A39: B01 | B39: INTER CARS MALTA LIMITED | C39: VEN0001490 | D39: =IFERROR(HYPERLINK(INDEX(вендори!F:F,MATCH(C39,вендори!A:A,0)),INDEX(вендори!F:F,MATCH(C39,вендори!A:A,0))),"") -> 0 | E39: SI25/B01/10/00008 | F39: BEAE41 | G39: AGX088MT | H39: MRKU2726589 | I39: SI25/B01/10/00008 | J39: 45940 | K39: AGX088MT | L39: 0 | M39: 13.96 | N39: 400 | O39: 392 | P39: -8 | Q39: Минус | R39: -111.68 | S39: -195.44 | T39: 45972 | U39: Анулирана | AA39: 8 | AB39: 46002 | AD39: 45993 | AE39: 45958 | AF39: 11 | AG39: MAGNUM TECHNOLOGY | AH39: MKEHAYOVA | AI39: SI25/B01/10/00008|BEAE41 | AN39: 30/10/2025 | AO39: 15904 | AP39: 7014
A40: B01 | B40: INTER CARS MALTA LIMITED | C40: VEN0001490 | D40: =IFERROR(HYPERLINK(INDEX(вендори!F:F,MATCH(C40,вендори!A:A,0)),INDEX(вендори!F:F,MATCH(C40,вендори!A:A,0))),"") -> 0 | E40: SI25/B01/10/00008 | F40: D6223A | G40: AGM088MT | H40: MRKU2726589 | I40: SI25/B01/10/00008 | J40: 45940 | K40: AGM088MT | L40: 0 | M40: 14.54 | N40: 200 | O40: 196 | P40: -4 | Q40: Минус | R40: -58.16 | S40: -101.78 | T40: 45972 | U40: Подадена | AE40: 45958 | AF40: 11 | AG40: MAGNUM TECHNOLOGY | AH40: MKEHAYOVA | AI40: SI25/B01/10/00008|D6223A | AN40: 30/10/2025 | AO40: 15905 | AP40: 7014
...

Sheet към доставчик
B1: INTER CARS BULGARIA CLAIM FORM - DELIVERY DISCREPANCIES
A2: B01 | B2: Supplier | C2: VEN0000779 | D2: деливъри задължително | E2: 2045269638 | F2: D006DB | G2: F 00V C17 504K | H2: Delivery | I2: Invoice No. | J2: Inv.date | K2: Ref. Number SUPPLIER | L2: F.00V.C17.504 | M2: 6.6 | N2: QTY invoiced | O2: QTY delivered | P2: Difference | Q2: Type of Difference | R2: 330 | S2: 645.4239 | T2: 26.6.2026 | AE2: 22.6.2026 | AG2: BOSCH | AH2: KMINKOV | AI2: 2045269638|D006DB | AQ2: delivery date
A3: B01 | B3: ContiTech Antriebssysteme GmbH | C3: VEN0000263 | D3: деливъри | E3: 3000223634 | F3: 321375 | G3: 4 PK 855 | I3: 3000223634 | J3: 46192 | K3: 4PK855 | L3: 4PK855 | M3: 3.48 | N3: 193 | O3: 213 | P3: 20 | Q3: =IF(P3>0,"surplus","short shipment") -> surplus | R3: 69.6 | S3: 136.12577 | T3: 46213 | U3: Подадена | AE3: 46205 | AG3: CONTITECH | AH3: VAPETROV | AI3: 3000223634|321375 | AQ3: 0400169017 | AR3: 004540
A4: B01 | B4: ContiTech Antriebssysteme GmbH | C4: VEN0000263 | D4: деливъри | E4: 3000223634 | F4: 262855 | G4: 4 PK 954 | I4: 3000223634 | J4: 46192 | K4: 4PK954 | L4: 4PK954 | M4: 4.51 | N4: 7 | O4: 14 | P4: 7 | Q4: =IF(P4>0,"surplus","short shipment") -> surplus | R4: 31.57 | S4: 61.745553 | T4: 46213 | U4: Подадена | AE4: 46205 | AG4: CONTITECH | AH4: VAPETROV | AI4: 3000223634|262855 | AQ4: 0400169017 | AR4: 000670
A5: B01 | B5: ContiTech Antriebssysteme GmbH | C5: VEN0000263 | D5: деливъри | E5: 3000223634 | F5: D67AA0 | G5: 5 PK 1150 K1 | I5: 3000223634 | J5: 46192 | K5: 5PK1150K1 | L5: 5PK1150K1 | M5: 22.27 | N5: 31 | O5: 25 | P5: -6 | Q5: =IF(P5>0,"surplus","short shipment") -> short shipment | R5: -133.62 | S5: -261.338 | T5: 46213 | U5: Подадена | AE5: 46205 | AG5: CONTITECH | AH5: VAPETROV | AI5: 3000223634|D67AA0 | AQ5: 0400120664 | AR5: 005730
A6: B01 | B6: ContiTech Antriebssysteme GmbH | C6: VEN0000263 | D6: деливъри | E6: 3000223634 | F6: B417A9 | G6: 6 PK 1670 | I6: 3000223634 | J6: 46192 | K6: 6PK1670 | L6: 6PK1670 | M6: 7.83 | N6: 25 | O6: 20 | P6: -5 | Q6: =IF(P6>0,"surplus","short shipment") -> short shipment | R6: -39.15 | S6: -76.570744 | T6: 46213 | U6: Подадена | AE6: 46205 | AG6: CONTITECH | AH6: VAPETROV | AI6: 3000223634|B417A9 | AQ6: 0400169017 | AR6: 003470
A7: B01 | B7: ContiTech Antriebssysteme GmbH | C7: VEN0000263 | D7: деливъри | E7: 3000223634 | F7: G1159K | G7: CT 1162 WP5 | I7: 3000223634 | J7: 46192 | K7: CT1162WP5 | L7: CT1162WP5 | M7: 63.1 | N7: 21 | O7: 20 | P7: -1 | Q7: =IF(P7>0,"surplus","short shipment") -> short shipment | R7: -63.1 | S7: -123.41287 | T7: 46213 | U7: Подадена | AE7: 46205 | AG7: CONTITECH | AH7: VAPETROV | AI7: 3000223634|G1159K | AQ7: 0400169017 | AR7: 005290
Q8: =IF(P8>0,"surplus","short shipment") -> short shipment
Q9: =IF(P9>0,"surplus","short shipment") -> short shipment
Q10: =IF(P10>0,"surplus","short shipment") -> short shipment
Q11: =IF(P11>0,"surplus","short shipment") -> short shipment
Q12: =IF(P12>0,"surplus","short shipment") -> short shipment
Q13: =IF(P13>0,"surplus","short shipment") -> short shipment
Q14: =IF(P14>0,"surplus","short shipment") -> short shipment
Q15: =IF(P15>0,"surplus","short shipment") -> short shipment
Q16: =IF(P16>0,"surplus","short shipment") -> short shipment
Q17: =IF(P17>0,"surplus","short shipment") -> short shipment
Q18: =IF(P18>0,"surplus","short shipment") -> short shipment
Q19: =IF(P19>0,"surplus","short shipment") -> short shipment
... Q168: =IF(P168>0,"surplus","short shipment") -> short shipment

Sheet вендори
A1: No. | B1: Name | C1: Currency Code | D1: Курс | E1: забележки, срокове, друго | F1: линк към сайт или спец.бланка
A2: VEN0000001 | B2: SC INTER CARS ROMANIA SRL | C2: EUR | D2: 1.95583
A3: VEN0000002 | B3: ОМВ БЪЛГАРИЯ ООД | C3: EUR | D3: 1.95583 | E3: от 01.01.26 вече е ЕВРО
A4: VEN0000003 | B4: INTER CARS SA | C4: EUR | D4: 1.95583
A5: VEN0000004 | B5: INTER CARS SA | C5: EUR | D5: 1.95583
A6: VEN0000005 | B6: ПРАКТИКЕР ЕООД | C6: EUR | D6: 1.95583 | E6: от 01.01.26 вече е ЕВРО
A7: VEN0000006 | B7: АГУРА ЕНД КО ЕООД | C7: EUR | D7: 1.95583 | E7: от 01.01.26 вече е ЕВРО
A8: VEN0000007 | B8: ШЕЛ БЪЛГАРИЯ ЕАД | C8: EUR | D8: 1.95583 | E8: от 01.01.26 вече е ЕВРО
A9: VEN0000008 | B9: МИДИЯ ИНВЕСТМЪНТ ЕООД | C9: EUR | D9: 1.95583 | E9: от 01.01.26 вече е ЕВРО
A10: VEN0000009 | B10: ЦЕНТЪР ЗА ПРЕВОДИ РЕЗОН ЕООД | C10: EUR | D10: 1.95583 | E10: от 01.01.26 вече е ЕВРО
A11: VEN0000010 | B11: НОТАРИУС МАРГАРИТА ИВАНЧЕВА | C11: EUR | D11: 1.95583 | E11: от 01.01.26 вече е ЕВРО
A12: VEN0000011 | B12: А1 БЪЛГАРИЯ ЕАД | C12: EUR | D12: 1.95583 | E12: от 01.01.26 вече е ЕВРО
A13: VEN0000012 | B13: ФУРНАРИ-ФФ ЕООД | C13: EUR | D13: 1.95583 | E13: от 01.01.26 вече е ЕВРО
A14: VEN0000013 | B14: КОНСУЛТИМ РИКРУИТМЪНТ ЕНД СЕЛЕ | C14: EUR | D14: 1.95583 | E14: от 01.01.26 вече е ЕВРО
A15: VEN0000014 | B15: БИСТРА И ГАЛИНА 2007 ЕООД | C15: EUR | D15: 1.95583 | E15: от 01.01.26 вече е ЕВРО
A16: VEN0000015 | B16: НОТАРИУС АЛЕКСАНДЪР ЧАКЪРОВ | C16: EUR | D16: 1.95583 | E16: от 01.01.26 вече е ЕВРО
A17: VEN0000016 | B17: ПЕТРОЛ АД | C17: EUR | D17: 1.95583 | E17: от 01.01.26 вече е ЕВРО
... A24: VEN0000023 | B24: БУЛГЕД ООД | C24: EUR | D24: 1.95583 | E24: от 01.01.26 вече е ЕВРО
A25: VEN0000024 | B25: АКОР - ПАНОНИЯ ХОТЕЛС ЗРТ | C25: HUF | D25: Check
A26: VEN0000025 | B26: О.С.Т. ГРАМАДА | C26: PLN | D26: 0.48
A27: VEN0000026 | B27: СЕРВИЗ ПЛЮС ООД | C27: EUR | D27: 1.95583 | E27: от 01.01.26 вече е ЕВРО
A28: VEN0000027 | B28: ТОДЕК ООД | C28: EUR | D28: 1.95583 | E28: от 01.01.26 вече е ЕВРО
A29: VEN0000028 | B29: ДАТЕКС ООД | C29: EUR | D29: 1.95583 | E29: от 01.01.26 вече е ЕВРО
A30: VEN0000029 | B30: МИРЕЛА ЕООД | C30: EUR | D30: 1.95583 | E30: от 01.01.26 вече е ЕВРО
A31: VEN0000030 | B31: БАРОМЕТЪР 31 ООД | C31: EUR | D31: 1.95583 | E31: от 01.01.26 вече е ЕВРО
A32: VEN0000031 | B32: МЕНИДЖМЪНТ ЕНД МАРКЕТИНГ ЕООД | C32: EUR | D32: 1.95583 | E32: от 01.01.26 вече е ЕВРО
A33: VEN0000032 | B33: СИСТЕМИ ЗА СИГУРНОСТ ЕООД | C33: EUR | D33: 1.95583 | E33: от 01.01.26 вече е ЕВРО
A34: VEN0000033 | B34: ПРОСЕТ ООД | C34: EUR | D34: 1.95583 | E34: от 01.01.26 вече е ЕВРО
A35: VEN0000034 | B35: ТЕД-ЕМ ООД | C35: EUR | D35: 1.95583 | E35: от 01.01.26 вече е ЕВРО
A36: VEN0000035 | B36: ХИТ ХИПЕРМАРКЕТ ЕООД | C36: EUR | D36: 1.95583 | E36: от 01.01.26 вече е ЕВРО
A37: VEN0000036 | B37: ИН ТАЙМ ООД | C37: EUR | D37: 1.95583 | E37: от 01.01.26 вече е ЕВРО
A38: VEN0000037 | B38: АДВ.ДРУЖ-ВО ДЕЛЧЕВ И ПАРТНЬОРИ | C38: EUR | D38: 1.95583 | E38: от 01.01.26 вече е ЕВРО
... A96: VEN0000095 | B96: ИЛИКОНИ ООД | C96: EUR | D96: 1.95583 | E96: от 01.01.26 вече е ЕВРО
A97: VEN0000096 | B97: PRACTICOM SRL | C97: EUR | D97: 1.95583
A98: VEN0000097 | B98: ЕЛИНА 97 ЕООД | C98: EUR | D98: 1.95583 | E98: от 01.01.26 вече е ЕВРО
A99: VEN0000098 | B99: ЕКОНТ ЕКСПРЕС ООД | C99: EUR | D99: 1.95583 | E99: от 01.01.26 вече е ЕВРО
A100: VEN0000099 | B100: БУЛТЕКС - 1 ООД | C100: EUR | D100: 1.95583 | E100: от 01.01.26 вече е ЕВРО
A101: VEN0000100 | B101: Ключарят ООД | C101: EUR | D101: 1.95583 | E101: от 01.01.26 вече е ЕВРО
A102: VEN0000101 | B102: ЕВРОМАРКЕТ КАРИ АД | C102: EUR | D102: 1.95583 | E102: от 01.01.26 вече е ЕВРО
A103: VEN0000102 | B103: ЛИФТ ООД | C103: EUR | D103: 1.95583 | E103: от 01.01.26 вече е ЕВРО
...

Sheet срокове
A1: Vendor No. | B1: Срок на подаване към доставчика - инфо от РМ | C1: Пълно име на вендора | D1: Забележка
A2: VEN0001181 | B2: няма ограничение, но възможно най-скоро | C2: ADRIAUTO
A3: VEN0001262 | B3: няма ограничение, но възможно най-скоро | C3: ASMET SP. Z O.O.
A4: VEN0001327 | B4: няма ограничение, но възможно най-скоро | C4: ASSO MARMITTE SRL
A5: VEN0001382 | B5: няма ограничение, но възможно най-скоро | C5: AUTO JUNTAS S.A.UNIPERSONAL
A6: VEN0000934 | B6: няма ограничение, но възможно най-скоро | C6: AUTOPART S.A.
A7: VEN0001258 | B7: няма ограничение | C7: BORGWARNER AFTERMARKET EUROPE GMBH
A8: VEN0001231 | B8: няма ограничение, но възможно най-скоро | C8: BOSAL AFTERMARKET EUROPE SPOL. S R.O.
A9: VEN0001264 | B9: няма ограничение, но възможно най-скоро | C9: CAFFARO SPÓŁKA Z OGR. ODPOWI. SP KOMANDYTOWA
A10: VEN0001275 | B10: 14 days, 14 дни | C10: CEI COSTRUZIONE EMILIANA INGRANAGGI SPA
A11: VEN0000766 | B11: няма ограничение, но възможно най-скоро | C11: Clarios Germany GmbH & Co. KGaA (CZ)
A12: VEN0001137 | B12: няма ограничение, но възможно най-скоро | C12: CONTINENTAL AFTERMARKET GMBH
A13: VEN0001616 | B13: няма ограничение, но възможно най-скоро | C13: CONTINENTAL TRADING GMBH
... A24: VEN0001317 | B24: 30 days since delivery date/ within 7 days after delivery date | C24: FEDERAL MOGUL GLOBAL AFTERMARKET EMEA BVBA HUNGARI
A25: VEN0001136 | B25: ASAP, възможно най-скоро | C25: FERDINAND BILSTEIN GMBH + CO. KG | D25: имаме 0,2% за рекламациии на база покупки - дефектни артикули се подават към отдел Рекламации
A26: VEN0001249 | B26: няма ограничение, но възможно най-скоро | C26: FRANCISCO ALBERO S.A.U.
A27: VEN0001243 | B27: няма ограничение, но възможно най-скоро | C27: FRECCIA INTERNATIONAL S.R.L. | D27: вече имат ексел -бланка и издават документите в началото на следващия месец
A28: VEN0001443 | B28: any discrepancies from deliveries should be reported within a maximum of 4 weeks after delivery | C28: GATES INDUSTRIAL EUROPE SARL
A29: VEN0001511 | B29: not to late (?) , не твърде късно | C29: GKN DRIVELINE SERVICE GMBH
A30: VEN0001253 | B30: two weeks after delivery on your warehouse. Till this time, we are able to check the status on camera . | C30: GROUP STEINHOF SP.Z.O.O | D30: We have to receive this kind of report till 3 weeks from delivery date .
A31: VEN0001281 | B31: няма ограничение | C31: HELLA POLSKA SP. Z O.O.
A32: VEN0001260 | B32: няма ограничение, но възможно най-скоро | C32: HERTH+BUSS FAHRZEUGTEILE GMBH & CO. KG
A33: VEN0001330 | B33: няма ограничение, но възможно най-скоро | C33: HIDRIA D.O.O.
A34: VEN0001555 | B34: няма ограничение, но възможно най-скоро | C34: HITACHI AUTOMOTIVE SYSTEMS ESPELKAMP GMBH
A35: VEN0001473 | B35: 7 days from receipt, 7 дни от доставката | C35: INDUSTRIAS DOLZ S.A.
A36: VEN0000925 | B36: няма ограничение, но възможно най-скоро | C36: INDUSTRIE SALERI ITALO S.P.A.
A37: VEN0001282 | B37: няма ограничение, но възможно най-скоро | C37: IPD INDUSTRIAL PARTS DISTRIBUTION GMBH
A38: VEN0000946 | B38: няма ограничение, но възможно най-скоро | C38: JENOX AKUMULATORY
A39: VEN0001241 | B39: 7 days from receiving , 7 дни от доставката | C39: KYB EUROPE GMBH
A40: VEN0001287 | B40: няма ограничение, но възможно най-скоро | C40: LAUBER SP. Z O.O.
A41: VEN0001285 | B41: ASAP, възможно най-скоро | C41: LE.MA SRL
A42: VEN0001242 | B42: not specified , не е подадена информация | C42: LESJOFORS SPRINGS GMBH
A43: VEN0001286 | B43: not specified , не е подадена информация | C43: LINEX SP. Z O.O.
A44: VEN0001908 | B44: not specified , не е подадена информация | C44: LORO | D44: sales@loro.com.pl
A45: VEN0001234 | B45: няма ограничение, но възможно най-скоро | C45: LPR SRL
A46: VEN0001316 | B46: Има ограничение - 7 дни от датата на получаване на стоката | C46: LUMILEDS POLAND S.A.
A47: VEN0000375 | B47: Има ограничение - 7 дни от датата на получаване на стоката | C47: Magneti Marelli Aftermarket
A48: VEN0001259 | B48: Има ограничение - 14 дни от датата на получаване на стоката | C48: MAHLE AFTERMARKET GMBH
A49: VEN0000533 | B49: Има ограничение - 14 дни от датата на получаване на стоката | C49: MANN HUMMEL GERMANY | D49: срокът за подаване е от 20.09.2024 - within 2 weeks after receiving the goods
A50: VEN0000282 | B50: няма ограничение, но възможно най-скоро | C50: MANN+HUMMEL FILTR. Sp. z o.o.
...

Sheet за счетоводството
F1: Вътр.№ | G1: Активен № | P1: к-во | V1: Документ № | W1: Дата на док. | X1: клетка | Y1: забележка
A2: B01 | B2: HEPU-Autoteile GmbH | C2: VEN0003385 | D2: 0 | E2: 2026403157 | F2: H0FPPW | G2: HEP21-0671 | H2: 62550 | 2026-403154 | I2: 2026-403157 | J2: 46161 | K2: 21-0671 | M2: 359.2 | N2: 1 | O2: 0 | P2: -1 | Q2: Минус | R2: -359.2 | S2: -702.53414 | T2: 46181 | U2: Получено КИ | V2: 2026-403605 | W2: 46183 | X2: =IF(P2<0,"B01-NOT-DELIV-DIRECT","прием") -> B01-NOT-DELIV-DIRECT | AE2: 46169 | AG2: HEPU | AH2: VAPETROV | AI2: 2026403157|H0FPPW | AN2: 46178 | AO2: 25812 | AP2: 13144
X3: =IF(P3<0,"B01-NOT-DELIV-DIRECT","прием") -> прием
X4: =IF(P4<0,"B01-NOT-DELIV-DIRECT","прием") -> прием
X5: =IF(P5<0,"B01-NOT-DELIV-DIRECT","прием") -> прием
X6: =IF(P6<0,"B01-NOT-DELIV-DIRECT","прием") -> прием
X7: =IF(P7<0,"B01-NOT-DELIV-DIRECT","прием") -> прием
X8: =IF(P8<0,"B01-NOT-DELIV-DIRECT","прием") -> прием
X9: =IF(P9<0,"B01-NOT-DELIV-DIRECT","прием") -> прием
X10: =IF(P10<0,"B01-NOT-DELIV-DIRECT","прием") -> прием
X11: =IF(P11<0,"B01-NOT-DELIV-DIRECT","прием") -> прием
X12: =IF(P12<0,"B01-NOT-DELIV-DIRECT","прием") -> прием
X13: =IF(P13<0,"B01-NOT-DELIV-DIRECT","прием") -> прием
X14: =IF(P14<0,"B01-NOT-DELIV-DIRECT","прием") -> прием
... X25: =IF(P25<0,"B01-NOT-DELIV-DIRECT","прием") -> прием

Sheet статуси и легенда цветове
A1: Подадена | H1: Легенда цветове на шрифта:
A2: Разлика под 50лв. | H2: 123456 | I2: направена е инв. От Митко - януари 2025, положителна - плюсове
A3: Получено КИ | H3: 123456 | I3: направена е инв. От Митко - януари 2025, отрицателна - минуси
A4: Получено ДИ/фактура | H4: 123456 | I4: подадени от Руми на месечна база за корекция към склада
A5: КИ и ДИ в един документ | H5: 123456 | I5: bold - намерени, които Руми още не проверила дали са подадени, или не (след обработка блод-а се маха)
A6: Изтекъл срок за подаване | H6: 123456 | I6: всички останали, стандартни
A7: За доуточняване | H7: 123456 | I7: специални, нещо за проверка, да се обърне внимание, да се провери, да се внимава за друга кореспондеция или нещо подобно
A8: одобрена от доставчика, чака документ | I8: ако са маркирани така, значи са счупени или повредени, но НЕ СА липси
A9: Отказани | I9: за проверка от Тони, склада (или бройките не са ок, или номерата, или се дублират, или има грешки в кроса - Руми)
A10: Анулирана
A11: За бракуване
A12: За връщане или върнато
A13: издадена ф-ра към ДД
A14: изпратени от дост.впосл.
A15: коригира се с ИНВЕНТАРИЗАЦИЯ
A16: МАСЛА - обработва се от РМ
A17: отказана, но впосл. НАМЕРЕНА в склада!
A18: отказана поради срок!
A19: Гуми или OE - обработва се от РМ
A20: Сервизно - обработва се от СО

Sheet В01 програма
A1: № | B1: Доставка № | C1: Доставчик | D1: Доставчик № | E1: Номер прием | F1: Вътрешен № | G1: Активен № | H1: Доставка № | I1: Quantity | J1: Плюс-Минус | K1: Тип | L1: Прием генериран на | M1: Зона | N1: Коментар | O1: Коментар Админ
A2: 27439 | B2: 14399 | C2: HSN TUNNEL-ROMIX | D2: VEN0001367 | E2: 000423/BLX/2026/UE | F2: BFD5D8 | G2: ROM C60332 | H2: 000423/BLX/2026/UE | I2: 60 | J2: Плюс | K2: Директни | L2: 46206 | M2: Ниво 3
A3: 27500 | B3: 13627 | C3: MANN HUMMEL GERMANY | D3: VEN0000533 | E3: 101275603 | F3: D06C2C | G3: C 27 1250/1 | H3: 980798 | I3: -42 | J3: Минус | K3: Директни | L3: 46184 | M3: Ниво 3
A4: 27502 | B4: 13627 | C4: MANN HUMMEL GERMANY | D4: VEN0000533 | E4: 101275603 | F4: H068NX | G4: TB 1374/13 X | H4: 980798 | I4: -10 | J4: Минус | K4: Директни | L4: 46184 | M4: Ниво 3
A5: 27501 | B5: 13627 | C5: MANN HUMMEL GERMANY | D5: VEN0000533 | E5: 101275603 | F5: D06F44 | G5: WP 12 300 | H5: 980798 | I5: -10 | J5: Минус | K5: Директни | L5: 46184 | M5: Ниво 3
A6: 27304 | B6: 14045 | C6: Valeo Service Eastern Europe | D6: VEN0000668 | E6: 111083178 | F6: G0QNP7 | G6: VAL200284 | H6: 26702302 | 26702303 | 26714082 | 26714087 | 26702159 | I6: -1 | J6: Минус | K6: Директни | L6: 46197 | M6: Ниво 0
A7: 27305 | B7: 14045 | C7: Valeo Service Eastern Europe | D7: VEN0000668 | E7: 111083178 | F7: G0UYL7 | G7: VAL440999 | H7: 26702302 | 26702303 | 26714082 | 26714087 | 26702159 | I7: -1 | J7: Минус | K7: Директни | L7: 46197 | M7: Ниво 0
A8: 27303 | B8: 14045 | C8: Valeo Service Eastern Europe | D8: VEN0000668 | E8: 111083178 | F8: F8E7A5 | G8: VAL837437 | H8: 26702302 | 26702303 | 26714082 | 26714087 | 26702159 | I8: -1 | J8: Минус | K8: Директни | L8: 46197 | M8: Ниво 0
A9: 27390 | B9: 14367 | C9: FERDINAND BILSTEIN GMBH | D9: VEN0001136 | E9: 12562980 | F9: 368512 | G9: FE01293 | H9: 709999390 | 709999391 | 709999384 | I9: 6 | J9: Плюс | K9: Директни | L9: 46206 | M9: Ниво 1
A10: 27362 | B10: 14385 | C10: MS MOTORSERVICE | D10: VEN0001314 | E10: 2430441852 | F10: AE9AAE | G10: 20190390600 | H10: 80821757 | 80821546 | I10: -1 | J10: Минус | K10: Директни | L10: 46206 | M10: Ниво 2
A11: 27363 | B11: 14385 | C11: MS MOTORSERVICE | D11: VEN0001314 | E11: 2430441864 | F11: DE38D3 | G11: 7.07381.00.0 | H11: 80821757 | 80821546 | I11: -1 | J11: Минус | K11: Директни | L11: 46206 | M11: Ниво 2
A12: 27293 | B12: 14353 | C12: MS MOTORSERVICE | D12: VEN0001314 | E12: 2430441874 | F12: C5D366 | G12: 20190220660 | H12: 80821756 | I12: 1 | J12: Плюс | K12: Директни | L12: 46205 | M12: Ниво 2
A13: 27291 | B13: 14353 | C13: MS MOTORSERVICE | D13: VEN0001314 | E13: 2430441874 | F13: C00D83 | G13: 7.00272.03.0 | H13: 80821756 | I13: 2 | J13: Плюс | K13: Директни | L13: 46205 | M13: Ниво 2
A14: 27292 | B14: 14353 | C14: MS MOTORSERVICE | D14: VEN0001314 | E14: 2430441874 | F14: H0FI7U | G14: 7.09460.15.0 | H14: 80821756 | I14: 1 | J14: Плюс | K14: Директни | L14: 46205 | M14: Ниво 2
A15: 27271 | B15: 14273 | C15: HANS PRIES DIRECT | D15: VEN0003766 | E15: 26-206216 | F15: G0KLIH | G15: HP117 457 | H15: 26-206216 | I15: -12 | J15: Минус | K15: Директни | L15: 46204 | M15: Ниво 2
A16: 27435 | B16: 14318 | C16: ContiTech Antriebssysteme GmbH | D16: VEN0000263 | E16: 3000223634 | F16: 321375 | G16: 4 PK 855 | H16: 60387227 | 60380482 | 60377473 | 60374288 | I16: 20 | J16: Плюс | K16: Директни | L16: 46205 | M16: Ниво 3
A17: 27433 | B17: 14318 | C17: ContiTech Antriebssysteme GmbH | D17: VEN0000263 | E17: 3000223634 | F17: 262855 | G17: 4 PK 954 | H17: 60387227 | 60380482 | 60377473 | 60374288 | I17: 7 | J17: Плюс | K17: Директни | L17: 46205 | M17: Ниво 3
A18: 27430 | B18: 14318 | C18: ContiTech Antriebssysteme GmbH | D18: VEN0000263 | E18: 3000223634 | F18: D67AA0 | G18: 5 PK 1150 K1 | H18: 60387227 | 60380482 | 60377473 | 60374288 | I18: -6 | J18: Минус | K18: Директни | L18: 46205 | M18: Ниво 3
A19: 27428 | B19: 14318 | C19: ContiTech Antriebssysteme GmbH | D19: VEN0000263 | E19: 3000223634 | F19: B417A9 | G19: 6 PK 1670 | H19: 60387227 | 60380482 | 60377473 | 60374288 | I19: -5 | J19: Минус | K19: Директни | L19: 46205 | M19: Ниво 3
A20: 27432 | B20: 14318 | C20: ContiTech Antriebssysteme GmbH | D20: VEN0000263 | E20: 3000223634 | F20: G1159K | G20: CT 1162 WP5 | H20: 60387227 | 60380482 | 60377473 | 60374288 | I20: -1 | J20: Минус | K20: Директни | L20: 46205 | M20: Ниво 3
A21: 27301 | B21: 14090 | C21: FEDERAL MOGUL EMEA | D21: VEN0001842 | E21: 3000739942 | F21: G0OC6W | G21: BCV29264TK | H21: 35591161 | I21: -5 | J21: Минус | K21: Директни | L21: 46198 | M21: Ниво 0
A22: 27311 | B22: 14090 | C22: FEDERAL MOGUL EMEA | D22: VEN0001842 | E22: 3000739952 | F22: 223620 | G22: 08-245200-00 | H22: 35591161 | I22: -10 | J22: Минус | K22: Директни | L22: 46198 | M22: Ниво 2
A23: 27309 | B23: 14090 | C23: FEDERAL MOGUL EMEA | D23: VEN0001842 | E23: 3000739952 | F23: D4876E | G23: BCR214A | H23: 35591161 | I23: -4 | J23: Минус | K23: Директни | L23: 46198 | M23: Ниво 2
A24: 27313 | B24: 14090 | C24: FEDERAL MOGUL EMEA | D24: VEN0001842 | E24: 3000739953 | F24: DC26DF | G24: CH-LS-10133 | H24: 35591161 | I24: -8 | J24: Минус | K24: Директни | L24: 46198 | M24: Ниво 2
A25: 27302 | B25: 14090 | C25: FEDERAL MOGUL EMEA | D25: VEN0001842 | E25: 3000739954 | F25: 315186 | G25: FVR1102 | H25: 35591161 | I25: -9 | J25: Минус | K25: Директни | L25: 46198 | M25: Ниво 0
A26: 27448 | B26: 14334 | C26: MAHLE AFTERMARKET GMBH | D26: VEN0001259 | E26: 398761474 | F26: G08FBW | G26: CFF 471 000P | H26: 6373593 | 6373594 | 6380449 | I26: -2 | J26: Минус | K26: Директни | L26: 46205 | M26: Ниво 2
A27: 27482 | B27: 13703 | C27: Schaeffler Automot.Aftermarket | D27: VEN0000463 | E27: 423692516 | F27: F8248C | G27: 544 0088 20 | H27: 62422496 | 62422234 | 62422519 | I27: -5 | J27: Минус | K27: Директни | L27: 46188 | M27: Ниво 1
A28: 27483 | B28: 13703 | C28: Schaeffler Automot.Aftermarket | D28: VEN0000463 | E28: 423692516 | F28: D0B031 | G28: 712 0580 10 | H28: 62422496 | 62422234 | 62422519 | I28: -18 | J28: Минус | K28: Директни | L28: 46188 | M28: Ниво 1
A29: 27299 | B29: 14247 | C29: Schaeffler Automot.Aftermarket | D29: VEN0000463 | E29: 423697416 | F29: A9965D | G29: 624 3103 33 | H29: 62438991 | 62438996 | I29: 1 | J29: Плюс | K29: Директни | L29: 46203 | M29: Ниво 0
A30: 27473 | B30: 14509 | C30: FROGUM DIRECT DELIVERYES | D30: VEN0002039 | E30: 5/ 7/SU/2026 | F30: G0X14X | G30: FRG77409460 | H30: 5/ 7/SU/2026 | I30: -2 | J30: Минус | K30: Директни | L30: 46210 | M30: Б. П.
A31: 27472 | B31: 14509 | C31: FROGUM DIRECT DELIVERYES | D31: VEN0002039 | E31: 5/ 7/SU/2026 | F31: D75935 | G31: MMT A040 00992W2 | H31: 5/ 7/SU/2026 | I31: -2 | J31: Минус | K31: Директни | L31: 46210 | M31: Б. П.
A32: 27446 | B32: 14343 | C32: ZF / FRIEDRICHSHAFEN AG | D32: VEN0001053 | E32: 5013860425 | F32: D701DB | G32: LMI36532 | H32: 166207035 | 166207118 | 166207119 | 166207141 | 166207164 | 166207036 | I32: -2 | J32: Минус | K32: Директни | L32: 46205 | M32: Ниво 1
A33: 27492 | B33: 14450 | C33: TRW / ZF- CZECH | D33: VEN0003781 | E33: 5013870887 | F33: AF39A8 | G33: DF4274BS | H33: 166156113 | 166188636 | 166188641 | I33: 1 | J33: Плюс | K33: Директни | L33: 46209 | M33: Ниво 0
A34: 27489 | B34: 14450 | C34: TRW / ZF- CZECH | D34: VEN0003781 | E34: 5013870887 | F34: B38D11 | G34: GDB1736 | H34: 166156113 | 166188636 | 166188641 | I34: -3 | J34: Минус | K34: Директни | L34: 46209 | M34: Ниво 0
A35: 27491 | B35: 14450 | C35: TRW / ZF- CZECH | D35: VEN0003781 | E35: 5013870887 | F35: BE20D0 | G35: GDB1847 | H35: 166156113 | 166188636 | 166188641 | I35: 3 | J35: Плюс | K35: Директни | L35: 46209 | M35: Ниво 0
A36: 27490 | B36: 14450 | C36: TRW / ZF- CZECH | D36: VEN0003781 | E36: 5013870887 | F36: BB905C | G36: PHB562 | H36: 166156113 | 166188636 | 166188641 | I36: -8 | J36: Минус | K36: Директни | L36: 46209 | M36: Ниво 0
A37: 27505 | B37: 14327 | C37: GATES | D37: VEN0001443 | E37: 5200011582 | F37: H07R6N | G37: GATK04T360HOB | H37: 80095534 | 80101230 | I37: -1 | J37: Минус | K37: Директни | L37: 46205 | M37: Ниво 3
A38: 27508 | B38: 14327 | C38: GATES | D38: VEN0001443 | E38: 5200011582 | F38: H0GOUL | G38: GATK05T360HOB | H38: 80095534 | 80101230 | I38: 1 | J38: Плюс | K38: Директни | L38: 46205 | M38: Ниво 3
A39: 27506 | B39: 14327 | C39: GATES | D39: VEN0001443 | E39: 5200012016 | F39: E4D086 | G39: GATK015537XS | H39: 80095534 | 80101230 | I39: -5 | J39: Минус | K39: Директни | L39: 46205 | M39: Ниво 3
A40: 27317 | B40: 14441 | C40: ОСРАМ СЕЙЛС ЕООД | D40: VEN0002997 | E40: 925012043 | F40: E65886 | G40: NLX233 K10SZT | H40: 925012043 | I40: -495 | J40: Минус | K40: Директни | L40: 46209 | M40: Ниво 3
...

Sheet работно поле
A1: 368512 | B1: | | D1: D06C2C | E1: | | F1: C 27 1250/1 | G1: -42 | I1: D06C2C | J1: 42 | K1: =G1+J1 -> 0
A2: C5D366 | B2: 52.39 | D2: H068NX | E2: | | F2: TB 1374/13 X | G2: -10 | I2: H068NX | J2: 10 | K2: =G2+J2 -> 0
A3: C00D83 | B3: 66.64 | D3: D06F44 | E3: | | F3: WP 12 300 | G3: -10 | I3: D06F44 | J3: 10 | K3: =G3+J3 -> 0
A4: G13XFN | B4: 30.8 | D4: G0QNP7 | E4: | | F4: VAL200284 | G4: -1 | I4: G0QNP7 | J4: 1 | K4: =G4+J4 -> 0
A5: AE56E7 | B5: 37.17 | D5: G0UYL7 | E5: | | F5: VAL440999 | G5: -1 | I5: G0UYL7 | J5: 1 | K5: =G5+J5 -> 0
A6: AE578A | B6: 43.65 | D6: F8E7A5 | E6: | | F6: VAL837437 | G6: -1 | I6: F8E7A5 | J6: 1 | K6: =G6+J6 -> 0
A7: G0K3M2 | B7: 147.97 | D7: AE9AAE | E7: | | F7: 20190390600 | G7: -1 | I7: AE9AAE | J7: 1 | K7: =G7+J7 -> 0
A8: G0YHEW | B8: 17.89 | D8: DE38D3 | E8: | | F8: 7.07381.00.0 | G8: -1 | I8: DE38D3 | J8: 1 | K8: =G8+J8 -> 0
A9: G0WNJF | B9: 18.28 | D9: G0KLIH | E9: | | F9: HP117 457 | G9: -12 | I9: G0KLIH | J9: 12 | K9: =G9+J9 -> 0
D10: D67AA0 | E10: | | F10: 5 PK 1150 K1 | G10: -6 | I10: D67AA0 | J10: 6 | K10: =G10+J10 -> 0
D11: B417A9 | E11: | | F11: 6 PK 1670 | G11: -5 | I11: B417A9 | J11: 5 | K11: =G11+J11 -> 0
D12: G1159K | E12: | | F12: CT 1162 WP5 | G12: -1 | I12: G1159K | J12: 1 | K12: =G12+J12 -> 0
D13: G0OC6W | E13: | | F13: BCV29264TK | G13: -5 | I13: G0OC6W | J13: 5 | K13: =G13+J13 -> 0
D14: 223620 | E14: | | F14: 08-245200-00 | G14: -10 | I14: 223620 | J14: 10 | K14: =G14+J14 -> 0
D15: D4876E | E15: | | F15: BCR214A | G15: -4 | I15: D4876E | J15: 4 | K15: =G15+J15 -> 0
D16: DC26DF | E16: | | F16: CH-LS-10133 | G16: -8 | I16: DC26DF | J16: 8 | K16: =G16+J16 -> 0
D17: 315186 | E17: | | F17: FVR1102 | G17: -9 | I17: 315186 | J17: 9 | K17: =G17+J17 -> 0
D18: G08FBW | E18: | | F18: CFF 471 000P | G18: -2 | I18: G08FBW | J18: 2 | K18: =G18+J18 -> 0
D19: F8248C | E19: | | F19: 544 0088 20 | G19: -5 | I19: F8248C | J19: 5 | K19: =G19+J19 -> 0
D20: D0B031 | E20: | | F20: 712 0580 10 | G20: -18 | I20: D0B031 | J20: 18 | K20: =G20+J20 -> 0
D21: G0X14X | E21: | | F21: FRG77409460 | G21: -2 | I21: G0X14X | J21: 2 | K21: =G21+J21 -> 0
D22: D75935 | E22: | | F22: MMT A040 00992W2 | G22: -2 | I22: D75935 | J22: 2 | K22: =G22+J22 -> 0
D23: D701DB | E23: | | F23: LMI36532 | G23: -2 | I23: D701DB | J23: 2 | K23: =G23+J23 -> 0
D24: B38D11 | E24: | | F24: GDB1736 | G24: -3 | I24: B38D11 | J24: 3 | K24: =G24+J24 -> 0
D25: BB905C | E25: | | F25: PHB562 | G25: -8 | I25: BB905C | J25: 8 | K25: =G25+J25 -> 0
D26: H07R6N | E26: | | F26: GATK04T360HOB | G26: -1 | I26: H07R6N | J26: 1 | K26: =G26+J26 -> 0
D27: E4D086 | E27: | | F27: GATK015537XS | G27: -5 | I27: E4D086 | J27: 5 | K27: =G27+J27 -> 0
D28: E65886 | E28: | | F28: NLX233 K10SZT | G28: -495 | I28: E65886 | J28: 495 | K28: =G28+J28 -> 0
D29: H0KLJA | E29: | | F29: OSR7506DWP-2BL | G29: -20 | I29: H0KLJA | J29: 20 | K29: =G29+J29 -> 0
... D39: 9F824A | E39: | | F39: AHP029MT | G39: -4 | I39: 9F824A | J39: 4 | K39: =G39+J39 -> 0
D40: H0HWRH | F40: 11033052HW | G40: -1 | I40: H0HWRH | J40: 1 | K40: =G40+J40 -> 0
